Workbook

Sheet Summary
A1: KYC Compliance Report
A3: Assumptions (edit the yellow cells)
A4: As-of date | B4: 46322
A5: SLA (days) | B5: 5
A7: Key metrics
A8: Total cases | B8: =COUNTA(Cases!$A$2:$A$482) -> 481
A9: Pending | B9: =COUNTIF(Cases!$F$2:$F$482,"Pending") -> 51
A10: Approved | B10: =COUNTIF(Cases!$F$2:$F$482,"Approved") -> 350
A11: Rejected | B11: =COUNTIF(Cases!$F$2:$F$482,"Rejected") -> 80
A12: Approval rate (of decided cases) | B12: =IFERROR(B10/(B10+B11),0) -> 0.81395349
A13: Average turnaround (days) | B13: =IFERROR(AVERAGE(Cases!$J$2:$J$482),0) -> 6.8418605
A14: Overdue pending cases | B14: =COUNTIFS(Cases!$F$2:$F$482,"Pending",Cases!$H$2:$H$482,"<"&($B$4-$B$5)) -> 35
A16: Cases by risk level and status
A17: Risk level | B17: Pending | C17: Approved | D17: Rejected | E17: Total
A18: Low | B18: =COUNTIFS(Cases!$E$2:$E$482,$A18,Cases!$F$2:$F$482,B$17) -> 30 | C18: =COUNTIFS(Cases!$E$2:$E$482,$A18,Cases!$F$2:$F$482,C$17) -> 213 | D18: =COUNTIFS(Cases!$E$2:$E$482,$A18,Cases!$F$2:$F$482,D$17) -> 47 | E18: =SUM(B18:D18) -> 290
A19: Medium | B19: =COUNTIFS(Cases!$E$2:$E$482,$A19,Cases!$F$2:$F$482,B$17) -> 15 | C19: =COUNTIFS(Cases!$E$2:$E$482,$A19,Cases!$F$2:$F$482,C$17) -> 105 | D19: =COUNTIFS(Cases!$E$2:$E$482,$A19,Cases!$F$2:$F$482,D$17) -> 25 | E19: =SUM(B19:D19) -> 145
A20: High | B20: =COUNTIFS(Cases!$E$2:$E$482,$A20,Cases!$F$2:$F$482,B$17) -> 6 | C20: =COUNTIFS(Cases!$E$2:$E$482,$A20,Cases!$F$2:$F$482,C$17) -> 32 | D20: =COUNTIFS(Cases!$E$2:$E$482,$A20,Cases!$F$2:$F$482,D$17) -> 8 | E20: =SUM(B20:D20) -> 46
A21: Total | B21: =SUM(B18:B20) -> 51 | C21: =SUM(C18:C20) -> 350 | D21: =SUM(D18:D20) -> 80 | E21: =SUM(E18:E20) -> 481
A23: Notes
A24: Source: cleaned KYC case data (Cases sheet); SQL-based analysis is on the SQL_* sheets.
A25: Overdue = Pending case submitted more than SLA days before the as-of date.
A26: As-of date and SLA are inputs (blue text, yellow fill); every metric above recalculates from them.
A27: Data_Issues lists the raw rows removed during cleaning and the reason.

Sheet Cases
A1: case_id | B1: customer_name | C1: document_type | D1: region | E1: risk_level | F1: status | G1: analyst | H1: submitted_date | I1: completed_date | J1: turnaround_days
A2: KYC-00305 | B2: Vivaan Verma | C2: Driving Licence | D2: East | E2: Medium | F2: Approved | G2: Analyst A | H2: 46273 | I2: 46284 | J2: =IF(I2="","",I2-H2) -> 11
A3: KYC-00500 | B3: Vivaan Khan | C3: Passport | D3: South | E3: Low | F3: Rejected | G3: Analyst D | H3: 46316 | I3: 46319 | J3: =IF(I3="","",I3-H3) -> 3
A4: KYC-00442 | B4: Vivaan Nair | C4: PAN Card | D4: South | E4: High | F4: Approved | G4: Analyst A | H4: 46221 | I4: 46233 | J4: =IF(I4="","",I4-H4) -> 12
A5: KYC-00154 | B5: Aditya Verma | C5: Passport | D5: West | E5: Low | F5: Rejected | G5: Analyst B | H5: 46255 | I5: 46262 | J5: =IF(I5="","",I5-H5) -> 7
A6: KYC-00074 | B6: Kabir Singh | C6: PAN Card | D6: West | E6: Medium | F6: Approved | G6: Analyst A | H6: 46243 | I6: 46251 | J6: =IF(I6="","",I6-H6) -> 8
A7: KYC-00132 | B7: Imran Ansari | C7: Address Proof | D7: South | E7: Low | F7: Approved | G7: Analyst C | H7: 46220 | I7: 46230 | J7: =IF(I7="","",I7-H7) -> 10
A8: KYC-00205 | B8: Arjun Singh | C8: Aadhaar | D8: South | E8: Low | F8: Pending | G8: Analyst B | H8: 46320 | J8: =IF(I8="","",I8-H8)
A9: KYC-00010 | B9: Aditya Mehta | C9: Address Proof | D9: West | E9: Low | F9: Approved | G9: Analyst A | H9: 46303 | I9: 46314 | J9: =IF(I9="","",I9-H9) -> 11
A10: KYC-00326 | B10: Arjun Joshi | C10: PAN Card | D10: West | E10: Low | F10: Approved | G10: Analyst B | H10: 46264 | I10: 46276 | J10: =IF(I10="","",I10-H10) -> 12
A11: KYC-00248 | B11: Imran Ansari | C11: Passport | D11: South | E11: Medium | F11: Approved | G11: Analyst A | H11: 46281 | I11: 46286 | J11: =IF(I11="","",I11-H11) -> 5
A12: KYC-00466 | B12: Ayesha Mehta | C12: Address Proof | D12: East | E12: Low | F12: Approved | G12: Analyst A | H12: 46283 | I12: 46295 | J12: =IF(I12="","",I12-H12) -> 12
A13: KYC-00354 | B13: Rohan Iyer | C13: Passport | D13: North | E13: Low | F13: Rejected | G13: Analyst B | H13: 46204 | I13: 46211 | J13: =IF(I13="","",I13-H13) -> 7
A14: KYC-00290 | B14: Ishaan Joshi | C14: Driving Licence | D14: East | E14: Low | F14: Rejected | G14: Analyst B | H14: 46299 | I14: 46309 | J14: =IF(I14="","",I14-H14) -> 10
A15: KYC-00085 | B15: Aditya Malik | C15: Address Proof | D15: West | E15: Low | F15: Approved | G15: Analyst B | H15: 46250 | I15: 46261 | J15: =IF(I15="","",I15-H15) -> 11
A16: KYC-00011 | B16: Meera Joshi | C16: Passport | D16: North | E16: Low | F16: Rejected | G16: Analyst A | H16: 46235 | I16: 46247 | J16: =IF(I16="","",I16-H16) -> 12
A17: KYC-00325 | B17: Sana Mehta | C17: Aadhaar | D17: South | E17: Medium | F17: Approved | G17: Analyst C | H17: 46294 | I17: 46306 | J17: =IF(I17="","",I17-H17) -> 12
A18: KYC-00079 | B18: Ishaan Malik | C18: Aadhaar | D18: East | E18: Low | F18: Rejected | G18: Analyst D | H18: 46264 | I18: 46270 | J18: =IF(I18="","",I18-H18) -> 6
A19: KYC-00031 | B19: Vivaan Ansari | C19: Aadhaar | D19: South | E19: Low | F19: Approved | G19: Analyst D | H19: 46283 | I19: 46289 | J19: =IF(I19="","",I19-H19) -> 6
A20: KYC-00185 | B20: Zara Nair | C20: PAN Card | D20: South | E20: Medium | F20: Approved | G20: Analyst B | H20: 46263 | I20: 46268 | J20: =IF(I20="","",I20-H20) -> 5
A21: KYC-00196 | B21: Ishaan Nair | C21: Address Proof | D21: South | E21: Low | F21: Pending | G21: Analyst B | H21: 46305 | J21: =IF(I21="","",I21-H21)
A22: KYC-00223 | B22: Tanvi Ansari | C22: Address Proof | D22: East | E22: Low | F22: Rejected | G22: Analyst D | H22: 46215 | I22: 46225 | J22: =IF(I22="","",I22-H22) -> 10
A23: KYC-00210 | B23: Riya Khan | C23: Address Proof | D23: East | E23: Low | F23: Rejected | G23: Analyst C | H23: 46258 | I23: 46270 | J23: =IF(I23="","",I23-H23) -> 12
A24: KYC-00282 | B24: Riya Sharma | C24: Address Proof | D24: West | E24: Low | F24: Approved | G24: Analyst A | H24: 46206 | I24: 46216 | J24: =IF(I24="","",I24-H24) -> 10
A25: KYC-00209 | B25: Arjun Sharma | C25: Address Proof | D25: North | E25: Low | F25: Approved | G25: Analyst A | H25: 46238 | I25: 46246 | J25: =IF(I25="","",I25-H25) -> 8
A26: KYC-00125 | B26: Ayesha Ansari | C26: Address Proof | D26: East | E26: High | F26: Pending | G26: Analyst D | H26: 46230 | J26: =IF(I26="","",I26-H26)
A27: KYC-00251 | B27: Imran Khan | C27: Address Proof | D27: West | E27: Low | F27: Pending | G27: Analyst A | H27: 46322 | J27: =IF(I27="","",I27-H27)
A28: KYC-00077 | B28: Ayesha Khan | C28: Driving Licence | D28: South | E28: High | F28: Approved | G28: Analyst C | H28: 46291 | I28: 46299 | J28: =IF(I28="","",I28-H28) -> 8
A29: KYC-00383 | B29: Arjun Sharma | C29: Passport | D29: East | E29: Low | F29: Approved | G29: Analyst B | H29: 46261 | I29: 46265 | J29: =IF(I29="","",I29-H29) -> 4
A30: KYC-00343 | B30: Rohan Iyer | C30: PAN Card | D30: West | E30: Low | F30: Rejected | G30: Analyst A | H30: 46276 | I30: 46277 | J30: =IF(I30="","",I30-H30) -> 1
A31: KYC-00324 | B31: Fatima Sharma | C31: Address Proof | D31: West | E31: Low | F31: Approved | G31: Analyst B | H31: 46261 | I31: 46268 | J31: =IF(I31="","",I31-H31) -> 7
A32: KYC-00245 | B32: Neha Reddy | C32: Address Proof | D32: North | E32: Medium | F32: Rejected | G32: Analyst D | H32: 46291 | I32: 46294 | J32: =IF(I32="","",I32-H32) -> 3
A33: KYC-00332 | B33: Aditya Khan | C33: Aadhaar | D33: South | E33: Medium | F33: Approved | G33: Analyst A | H33: 46234 | I33: 46242 | J33: =IF(I33="","",I33-H33) -> 8
A34: KYC-00141 | B34: Riya Verma | C34: Driving Licence | D34: North | E34: Low | F34: Approved | G34: Analyst B | H34: 46216 | I34: 46227 | J34: =IF(I34="","",I34-H34) -> 11
A35: KYC-00073 | B35: Neha Iyer | C35: Address Proof | D35: West | E35: Low | F35: Approved | G35: Analyst C | H35: 46264 | I35: 46266 | J35: =IF(I35="","",I35-H35) -> 2
A36: KYC-00401 | B36: Meera Nair | C36: Driving Licence | D36: West | E36: Medium | F36: Rejected | G36: Analyst D | H36: 46279 | I36: 46281 | J36: =IF(I36="","",I36-H36) -> 2
A37: KYC-00488 | B37: Kabir Nair | C37: PAN Card | D37: South | E37: Low | F37: Pending | G37: Analyst C | H37: 46321 | J37: =IF(I37="","",I37-H37)
A38: KYC-00226 | B38: Arjun Joshi | C38: Aadhaar | D38: North | E38: Low | F38: Approved | G38: Analyst D | H38: 46266 | I38: 46271 | J38: =IF(I38="","",I38-H38) -> 5
A39: KYC-00178 | B39: Riya Mehta | C39: Driving Licence | D39: West | E39: Medium | F39: Pending | G39: Analyst C | H39: 46322 | J39: =IF(I39="","",I39-H39)
A40: KYC-00404 | B40: Meera Verma | C40: Driving Licence | D40: West | E40: Low | F40: Approved | G40: Analyst C | H40: 46252 | I40: 46255 | J40: =IF(I40="","",I40-H40) -> 3
...

Sheet SQL_Turnaround_by_Doc
A1: document_type | B1: closed_cases | C1: avg_turnaround_days | D1: max_turnaround_days
A2: PAN Card | B2: 82 | C2: 7.1 | D2: 12
A3: Aadhaar | B3: 85 | C3: 7.1 | D3: 12
A4: Passport | B4: 76 | C4: 6.9 | D4: 12
A5: Driving Licence | B5: 88 | C5: 6.6 | D5: 12
A6: Address Proof | B6: 99 | C6: 6.6 | D6: 12

Sheet SQL_Analyst_Performance
A1: analyst | B1: total_cases | C1: approved | D1: rejected | E1: pending | F1: avg_turnaround_days
A2: Analyst A | B2: 130 | C2: 98 | D2: 20 | E2: 12 | F2: 7
A3: Analyst D | B3: 120 | C3: 83 | D3: 22 | E3: 15 | F3: 6.8
A4: Analyst B | B4: 116 | C4: 81 | D4: 19 | E4: 16 | F4: 7
A5: Analyst C | B5: 115 | C5: 88 | D5: 19 | E5: 8 | F5: 6.6

Sheet SQL_Monthly_Trend
A1: month | B1: submitted | C1: approved | D1: rejected | E1: pending
A2: 2026-06 | B2: 3 | C2: 1 | D2: 1 | E2: 1
A3: 2026-07 | B3: 126 | C3: 96 | D3: 22 | E3: 8
A4: 2026-08 | B4: 119 | C4: 86 | D4: 25 | E4: 8
A5: 2026-09 | B5: 122 | C5: 96 | D5: 20 | E5: 6
A6: 2026-10 | B6: 111 | C6: 71 | D6: 12 | E6: 28

Sheet Overdue_Cases
A1: case_id | B1: customer_name | C1: document_type | D1: region | E1: risk_level | F1: analyst | G1: submitted_date | H1: days_pending
A2: KYC-00125 | B2: Ayesha Ansari | C2: Address Proof | D2: East | E2: High | F2: Analyst D | G2: 2026-07-27 | H2: 92
A3: KYC-00270 | B3: Ayesha Nair | C3: Passport | D3: North | E3: High | F3: Analyst D | G3: 2026-09-04 | H3: 53
A4: KYC-00225 | B4: Kabir Malik | C4: Address Proof | D4: North | E4: High | F4: Analyst B | G4: 2026-09-11 | H4: 46
A5: KYC-00246 | B5: Aditya Mehta | C5: PAN Card | D5: West | E5: High | F5: Analyst A | G5: 2026-10-18 | H5: 9
A6: KYC-00428 | B6: Tanvi Nair | C6: PAN Card | D6: South | E6: Medium | F6: Analyst A | G6: 2026-07-19 | H6: 100
A7: KYC-00152 | B7: Riya Ansari | C7: Passport | D7: West | E7: Medium | F7: Analyst D | G7: 2026-07-28 | H7: 91
A8: KYC-00350 | B8: Ayesha Nair | C8: Address Proof | D8: North | E8: Medium | F8: Analyst A | G8: 2026-08-01 | H8: 87
A9: KYC-00068 | B9: Kabir Mehta | C9: Address Proof | D9: West | E9: Medium | F9: Analyst B | G9: 2026-08-01 | H9: 87
A10: KYC-00316 | B10: Zara Gupta | C10: Address Proof | D10: West | E10: Medium | F10: Analyst D | G10: 2026-08-05 | H10: 83
A11: KYC-00362 | B11: Riya Iyer | C11: Passport | D11: West | E11: Medium | F11: Analyst D | G11: 2026-08-23 | H11: 65
A12: KYC-00184 | B12: Zara Malik | C12: PAN Card | D12: South | E12: Medium | F12: Analyst A | G12: 2026-08-31 | H12: 57
A13: KYC-00134 | B13: Fatima Gupta | C13: PAN Card | D13: South | E13: Medium | F13: Analyst B | G13: 2026-09-27 | H13: 30
... A36: KYC-00017 | B36: Vivaan Gupta | C36: Passport | D36: South | E36: Low | F36: Analyst C | G36: 2026-10-18 | H36: 9

Sheet Data_Issues
A1: case_id | B1: reason
A2: KYC-00010 | B2: duplicate case_id
A3: KYC-00074 | B3: duplicate case_id
A4: KYC-00125 | B4: duplicate case_id
A5: KYC-00195 | B5: duplicate case_id
A6: KYC-00156 | B6: duplicate case_id
A7: KYC-00085 | B7: duplicate case_id
A8: KYC-00451 | B8: duplicate case_id
A9: KYC-00395 | B9: duplicate case_id
A10: KYC-00362 | B10: duplicate case_id
A11: KYC-00378 | B11: duplicate case_id
A12: KYC-00375 | B12: duplicate case_id
... A35: KYC-00464 | B35: completed_date earlier than submitted_date
